Traceback (most recent call last):
  File "/Users/emiresenov/jaxrc/case0inv/main.py", line 38, in <module>
    app.run(main)
  File "/opt/anaconda3/lib/python3.11/site-packages/absl/app.py", line 308, in run
    _run_main(main, args)
  File "/opt/anaconda3/lib/python3.11/site-packages/absl/app.py", line 254, in _run_main
    sys.exit(main(argv))
             ^^^^^^^^^^
  File "/Users/emiresenov/jaxrc/case0inv/main.py", line 33, in main
    train.train_and_evaluate(FLAGS.config, FLAGS.workdir)
  File "/Users/emiresenov/jaxrc/case0inv/train.py", line 41, in train_and_evaluate
    model = models.CaseZero(config, t_star)
            ^^^^^^^^^^^^^^^^^^^^^^^^^^^^^^^
  File "/Users/emiresenov/jaxrc/case0inv/models.py", line 15, in __init__
    super().__init__(config)
  File "/opt/anaconda3/lib/python3.11/site-packages/jaxpi/models.py", line 224, in __init__
    self.state = _create_inv_train_state(config)
                 ^^^^^^^^^^^^^^^^^^^^^^^^^^^^^^^
  File "/opt/anaconda3/lib/python3.11/site-packages/jaxpi/models.py", line 117, in _create_inv_train_state
    tx = _create_optimizer(config.optim)
         ^^^^^^^^^^^^^^^^^^^^^^^^^^^^^^^
  File "/opt/anaconda3/lib/python3.11/site-packages/jaxpi/models.py", line 71, in _create_optimizer
    tx = optax.lbfgs(
         ^^^^^^^^^^^^
TypeError: lbfgs() got an unexpected keyword argument 'line_search'
