Waiting for JIT...
Traceback (most recent call last):
  File "/Users/esenov/Documents/GitHub/inverse-RC/tempfieldcase1/main.py", line 41, in <module>
    app.run(main)
  File "/opt/anaconda3/lib/python3.12/site-packages/absl/app.py", line 308, in run
    _run_main(main, args)
  File "/opt/anaconda3/lib/python3.12/site-packages/absl/app.py", line 254, in _run_main
    sys.exit(main(argv))
             ^^^^^^^^^^
  File "/Users/esenov/Documents/GitHub/inverse-RC/tempfieldcase1/main.py", line 33, in main
    train.train_and_evaluate(FLAGS.config, FLAGS.workdir)
  File "/Users/esenov/Documents/GitHub/inverse-RC/tempfieldcase1/train.py", line 52, in train_and_evaluate
    model.state = model.step(model.state, batch)
                  ^^^^^^^^^^^^^^^^^^^^^^^^^^^^^^
  File "/opt/anaconda3/lib/python3.12/site-packages/jaxpi/models.py", line 177, in step
    grads = grad(self.loss)(state.params, state.weights, batch, *args)
            ^^^^^^^^^^^^^^^^^^^^^^^^^^^^^^^^^^^^^^^^^^^^^^^^^^^^^^^^^^
  File "/opt/anaconda3/lib/python3.12/site-packages/jaxpi/models.py", line 131, in loss
    weighted_losses = tree_map(lambda x, y: x * y, losses, weights)
                      ^^^^^^^^^^^^^^^^^^^^^^^^^^^^^^^^^^^^^^^^^^^^^
ValueError: Dict key mismatch; expected keys: ['data1', 'ics', 'res']; dict: {'data': Traced<ShapedArray(float32[], weak_type=True)>with<DynamicJaxprTrace>, 'ics': Traced<ShapedArray(float32[], weak_type=True)>with<DynamicJaxprTrace>, 'res': Traced<ShapedArray(float32[], weak_type=True)>with<DynamicJaxprTrace>}.
--------------------
For simplicity, JAX has removed its internal frames from the traceback of the following exception. Set JAX_TRACEBACK_FILTERING=off to include these.
