Traceback (most recent call last):
  File "/opt/anaconda3/lib/python3.11/site-packages/ml_collections/config_dict/config_dict.py", line 947, in __getitem__
    field = self._fields[key]
            ~~~~~~~~~~~~^^^^^
KeyError: 'inverse_params'

During handling of the above exception, another exception occurred:

Traceback (most recent call last):
  File "/opt/anaconda3/lib/python3.11/site-packages/ml_collections/config_dict/config_dict.py", line 849, in __getattr__
    return self[attribute]
           ~~~~^^^^^^^^^^^
  File "/opt/anaconda3/lib/python3.11/site-packages/ml_collections/config_dict/config_dict.py", line 953, in __getitem__
    raise KeyError(self._generate_did_you_mean_message(key, str(e)))
KeyError: "'inverse_params'"

During handling of the above exception, another exception occurred:

Traceback (most recent call last):
  File "/Users/emiresenov/jaxrc/case0inv/main.py", line 38, in <module>
    app.run(main)
  File "/opt/anaconda3/lib/python3.11/site-packages/absl/app.py", line 308, in run
    _run_main(main, args)
  File "/opt/anaconda3/lib/python3.11/site-packages/absl/app.py", line 254, in _run_main
    sys.exit(main(argv))
             ^^^^^^^^^^
  File "/Users/emiresenov/jaxrc/case0inv/main.py", line 33, in main
    train.train_and_evaluate(FLAGS.config, FLAGS.workdir)
  File "/Users/emiresenov/jaxrc/case0inv/train.py", line 41, in train_and_evaluate
    model = models.CaseZero(config, t_star)
            ^^^^^^^^^^^^^^^^^^^^^^^^^^^^^^^
  File "/Users/emiresenov/jaxrc/case0inv/models.py", line 15, in __init__
    super().__init__(config)
  File "/opt/anaconda3/lib/python3.11/site-packages/jaxpi/models.py", line 221, in __init__
    self.state = _create_inv_train_state(config)
                 ^^^^^^^^^^^^^^^^^^^^^^^^^^^^^^^
  File "/opt/anaconda3/lib/python3.11/site-packages/jaxpi/models.py", line 110, in _create_inv_train_state
    params['params'].update(config.inverse_params)
                            ^^^^^^^^^^^^^^^^^^^^^
  File "/opt/anaconda3/lib/python3.11/site-packages/ml_collections/config_dict/config_dict.py", line 851, in __getattr__
    raise AttributeError(e)
AttributeError: "'inverse_params'"
