Waiting for JIT...
Traceback (most recent call last):
  File "/Users/emiresenov/jaxrc/burgers1d/main.py", line 38, in <module>
    app.run(main)
  File "/opt/anaconda3/lib/python3.11/site-packages/absl/app.py", line 308, in run
    _run_main(main, args)
  File "/opt/anaconda3/lib/python3.11/site-packages/absl/app.py", line 254, in _run_main
    sys.exit(main(argv))
             ^^^^^^^^^^
  File "/Users/emiresenov/jaxrc/burgers1d/main.py", line 33, in main
    train.train_and_evaluate(FLAGS.config, FLAGS.workdir)
  File "/Users/emiresenov/jaxrc/burgers1d/train.py", line 51, in train_and_evaluate
    model.state = model.step(model.state, batch)
                  ^^^^^^^^^^^^^^^^^^^^^^^^^^^^^^
  File "/opt/anaconda3/lib/python3.11/site-packages/jaxpi/models.py", line 171, in step
    grads = grad(self.loss)(state.params, state.weights, batch, *args)
            ^^^^^^^^^^^^^^^^^^^^^^^^^^^^^^^^^^^^^^^^^^^^^^^^^^^^^^^^^^
  File "/opt/anaconda3/lib/python3.11/site-packages/jaxpi/models.py", line 124, in loss
    losses = self.losses(params, batch, *args)
             ^^^^^^^^^^^^^^^^^^^^^^^^^^^^^^^^^
  File "/Users/emiresenov/jaxrc/burgers1d/models.py", line 56, in losses
    u_pred = vmap(self.u_net, (0, None))(params, self.t0)
             ^^^^^^^^^^^^^^^^^^^^^^^^^^^^^^^^^^^^^^^^^^^^
ValueError: vmap got inconsistent sizes for array axes to be mapped:
  * most axes (8 of them) had size 256, e.g. axis 0 of argument params['params']['Dense_0']['bias'] of type float32[256];
  * some axes (2 of them) had size 1, e.g. axis 0 of argument params['params']['Dense_0']['kernel'] of type float32[1,256]
--------------------
For simplicity, JAX has removed its internal frames from the traceback of the following exception. Set JAX_TRACEBACK_FILTERING=off to include these.
