Waiting for JIT...
Traceback (most recent call last):
  File "/Users/emiresenov/jaxrc/examples/rc/main.py", line 42, in <module>
    app.run(main)
  File "/opt/anaconda3/lib/python3.11/site-packages/absl/app.py", line 308, in run
    _run_main(main, args)
  File "/opt/anaconda3/lib/python3.11/site-packages/absl/app.py", line 254, in _run_main
    sys.exit(main(argv))
             ^^^^^^^^^^
  File "/Users/emiresenov/jaxrc/examples/rc/main.py", line 34, in main
    train.train_and_evaluate(FLAGS.config, FLAGS.workdir)
  File "/Users/emiresenov/jaxrc/examples/rc/train.py", line 63, in train_and_evaluate
    log_dict = evaluator(state, batch, u_ref)
               ^^^^^^^^^^^^^^^^^^^^^^^^^^^^^^
  File "/Users/emiresenov/jaxrc/examples/rc/models.py", line 128, in __call__
    self.log_errors(state.params, u_ref)
  File "/Users/emiresenov/jaxrc/examples/rc/models.py", line 110, in log_errors
    l2_error = self.model.compute_l2_error(params, u_ref)
               ^^^^^^^^^^^^^^^^^^^^^^^^^^^^^^^^^^^^^^^^^^
  File "/Users/emiresenov/jaxrc/examples/rc/models.py", line 99, in compute_l2_error
    u_pred = self.u_pred_fn(params, self.t_star)
             ^^^^^^^^^^^^^^^^^^^^^^^^^^^^^^^^^^^
ValueError: vmap in_axes must be an int, None, or a tuple of entries corresponding to the positional arguments passed to the function, but got len(in_axes)=3, len(args)=2
--------------------
For simplicity, JAX has removed its internal frames from the traceback of the following exception. Set JAX_TRACEBACK_FILTERING=off to include these.
