Waiting for JIT...
Traceback (most recent call last):
  File "/opt/anaconda3/lib/python3.11/site-packages/jax/_src/api.py", line 1020, in _get_axis_size
    return shape[axis]
           ~~~~~^^^^^^
IndexError: tuple index out of range

The above exception was the direct cause of the following exception:

Traceback (most recent call last):
  File "/Users/emiresenov/jaxrc/case0inv/main.py", line 38, in <module>
    app.run(main)
  File "/opt/anaconda3/lib/python3.11/site-packages/absl/app.py", line 308, in run
    _run_main(main, args)
  File "/opt/anaconda3/lib/python3.11/site-packages/absl/app.py", line 254, in _run_main
    sys.exit(main(argv))
             ^^^^^^^^^^
  File "/Users/emiresenov/jaxrc/case0inv/main.py", line 33, in main
    train.train_and_evaluate(FLAGS.config, FLAGS.workdir)
  File "/Users/emiresenov/jaxrc/case0inv/train.py", line 54, in train_and_evaluate
    model.state = model.update_weights(model.state, batch)
                  ^^^^^^^^^^^^^^^^^^^^^^^^^^^^^^^^^^^^^^^^
  File "/opt/anaconda3/lib/python3.11/site-packages/jaxpi/models.py", line 187, in update_weights
    weights = self.compute_weights(state.params, batch, *args)
              ^^^^^^^^^^^^^^^^^^^^^^^^^^^^^^^^^^^^^^^^^^^^^^^^
  File "/opt/anaconda3/lib/python3.11/site-packages/jaxpi/models.py", line 173, in compute_weights
    ntk = self.compute_diag_ntk(params, batch, *args)
          ^^^^^^^^^^^^^^^^^^^^^^^^^^^^^^^^^^^^^^^^^^^
  File "/Users/emiresenov/jaxrc/case0inv/models.py", line 74, in compute_diag_ntk
    ics_ntk = vmap(ntk_fn, (None, None, 0))(
              ^^^^^^^^^^^^^^^^^^^^^^^^^^^^^^
ValueError: vmap was requested to map its argument along axis 0, which implies that its rank should be at least 1, but is only 0 (its shape is ())
--------------------
For simplicity, JAX has removed its internal frames from the traceback of the following exception. Set JAX_TRACEBACK_FILTERING=off to include these.
